Workbook

Sheet DASHBOARD
B2: 🏛 LOHAGARA PROVATI YOUTH ORGANIZATION
B3: Kamar Pukur Par, Uzir Hat, Lohagara, Chittagong · MANAGEMENT CONTROL DASHBOARD
B5: 📊 KEY PERFORMANCE INDICATORS
B6: 🏦 Net Fund (BDT) | K6: DPS Investment | L6: =B15 -> 2050000
B7: ='Central Fund Control'!B20 -> 5036580.2 | K7: FDR Investment | L7: =D15 -> 500000
B8: 👥 Total Members | D8: 📋 Total Shares | F8: 💰 Per Share/Month | H8: 📈 Expected Total | K8: Savings Balance | L8: =F15 -> 491280.17
B9: =COUNTA('Member Wise Deposit Summary'!$B$4:$B$80) -> 77 | D9: ='Member Wise Deposit Summary'!E81 -> 125 | F9: 1000 | H9: =125*1000*(COUNTIF('Month Wise Collection Summary'!C4:C10,">0")+COUNTIF('Month Wise Collection Summary'!C12:C23,">0")+COUNTIF('Month Wise Collection Summary'!C25:C36,">0")+COUNTIF('Month Wise Collection Summary'!C38:C49,">0")+COUNTIF('Month Wise Collection Summary'!C51:C62,">0")+COUNTIF('Month Wise Collection Summary'!C64:C75,">0")) -> 5125000 | K9: CNG Due | L9: =H15 -> 1239500
B10: ✅ Regular Collection | D10: ⏩ Advance Collection | F10: ⏳ Due Collection | H10: ⚠ Fine Collection | K10: Loan Due | L10: =H13 -> 758600
B11: ='Month Wise Collection Summary'!C77 -> 4493000 | D11: ='Month Wise Collection Summary'!D77 -> 216000 | F11: ='Month Wise Collection Summary'!E77 -> 375000 | H11: ='Month Wise Collection Summary'!F77 -> 23150
B12: 🎫 Entry Fee (BDT) | D12: 💸 Total Expenses | F12: 📊 Reconciliation | H12: 🏛 Loan Receivable
B13: ='Member Wise Deposit Summary'!F81 -> 12500 | D13: ='Month Wise Collection Summary'!H77 -> 83069.83 | F13: =IF(SUM((B11+D11+F11+H11+B13+B17))=SUM(D13+H13+B15+D15+F15+H15),"✔ BALANCED","⚠ WARNING — MISMATCH DETECTED") -> ✔ BALANCED | H13: ='Central Fund Control'!D9 -> 758600
B14: 🏧 DPS Investment | D14: 🏛 FDR Investment | F14: 💳 Savings Balance | H14: 🚗 CNG Receivable
B15: ='Central Fund Control'!D5 -> 2050000 | D15: ='Central Fund Control'!D6 -> 500000 | F15: ='Central Fund Control'!D7 -> 491280.17 | H15: ='Central Fund Control'!D8 -> 1239500
B16: Savings A/c Interest
B17: ='Central Fund Control'!B10 -> 2800
B19: 🗂 QUICK NAVIGATION — Click any button to jump to that sheet
B20: =HYPERLINK("#'Member Wise Deposit Summary'!A1","👥 Member Deposits") -> 👥 Member Deposits | D20: =HYPERLINK("#'Month Wise Collection Summary'!A1","📅 Monthly Collections") -> 📅 Monthly Collections | F20: =HYPERLINK("#'Month Wise Expenses'!A1","💸 Month Expenses") -> 💸 Month Expenses | H20: =HYPERLINK("#'Monthly Collection-2023'!A1","📋 Collection 2023") -> 📋 Collection 2023
B21: =HYPERLINK("#'Monthly Collection-2024)'!A1","📋 Collection 2024") -> 📋 Collection 2024 | D21: =HYPERLINK("#'Monthly Collection-2025'!A1","📋 Collection 2025") -> 📋 Collection 2025 | F21: =HYPERLINK("#'Monthly Collection-2026'!A1","📋 Collection 2026") -> 📋 Collection 2026 | H21: =HYPERLINK("#'Monthly Collection-2027'!A1","📋 Collection 2027") -> 📋 Collection 2027
B22: =HYPERLINK("#'Monthly Collection-2028'!A1","📋 Collection 2028") -> 📋 Collection 2028 | D22: =HYPERLINK("#'CNG 1 (Zohir Ahmed)'!A1","🚗 CNG 1 – Zohir") -> 🚗 CNG 1 – Zohir | F22: =HYPERLINK("#'CNG 2 (Abu Taher)'!A1","🚗 CNG 2 – Taher") -> 🚗 CNG 2 – Taher | H22: =HYPERLINK("#'CNG 3 (Zahedul Islam)'!A1","🚗 CNG 3 – Zahedul") -> 🚗 CNG 3 – Zahedul
B23: =HYPERLINK("#'CNG 4 (Sajal Barua)'!A1","🚗 CNG 4 – Sajal") -> 🚗 CNG 4 – Sajal | D23: =HYPERLINK("#'CNG 5 (Nurul Abser)'!A1","🚗 CNG 5 – Nurul") -> 🚗 CNG 5 – Nurul | F23: =HYPERLINK("#'CNG 6 (Abdul Malek)'!A1","🚗 CNG 6 – Malek") -> 🚗 CNG 6 – Malek | H23: =HYPERLINK("#'Auto Rikshwa (Kamal Uddin)'!A1","🚗 Auto – Kamal") -> 🚗 Auto – Kamal
B24: =HYPERLINK("#'CNG 7 (Md. Yousof)'!A1","🚗 CNG 7 – Yousof") -> 🚗 CNG 7 – Yousof | D24: =HYPERLINK("#'CNG 8 (Md. Alamgir'!A1","🚗 CNG 8 – Alamgir") -> 🚗 CNG 8 – Alamgir | F24: =HYPERLINK("#'CNG Summary'!A1","📈 CNG Summary") -> 📈 CNG Summary | H24: =HYPERLINK("#'Month Wise CNG Instlmnt Summary'!A1","📉 Month Wise CNG Installment Summary") -> 📉 Month Wise CNG Installment Summary
B25: =HYPERLINK("#'Loan Collection Summary'!A1","💼 Loan Summary") -> 💼 Loan Summary | D25: =HYPERLINK("#'Central Fund Control'!A1","🏦 Fund Control") -> 🏦 Fund Control | F25: =HYPERLINK("#'Investment Register'!A1","💹 Investments") -> 💹 Investments | H25: =HYPERLINK("#'Profit & Loss'!A1","📉 P&L Statement") -> 📉 P&L Statement
B26: =HYPERLINK("#'Share Maturity'!A1","🏁 Share Maturity") -> 🏁 Share Maturity | D26: =HYPERLINK("#'Member Final Receivable'!A1","👤 Final Receivable") -> 👤 Final Receivable
B27: Lohagara Provati Youth Organization · Dashboard v2.0 · Values auto-calculated from source sheets

Sheet Member Wise Deposit Summary
A1: =HYPERLINK("#DASHBOARD!A1","⬅ Dashboard") -> ⬅ Dashboard
B2: Lohagara Provati Youth Organization Kamar Pukur Par, Uzir Hat, Lohagara, Chittagong.
B3: Member ID | C3: Name | D3: Mobile Number | E3: Number of Shares | F3: Entry Fee (Per Share Tk.100/=) | G3: Till Date Total Deposit | H3: Total Fine | I3: Status
B4: ='Monthly Collection-2023'!B4 -> 1 | C4: ='Monthly Collection-2023'!C4 -> Monjurul Islam | D4: 1814824030 | E4: ='Monthly Collection-2023'!E4 -> 3 | F4: =E4*100 -> 300 | G4: ='Monthly Collection-2023'!AH4+'Monthly Collection-2024)'!BB4+'Monthly Collection-2025'!BB4+'Monthly Collection-2026'!BB4+'Monthly Collection-2027'!BB4+'Monthly Collection-2028'!BB4 -> 123000 | H4: ='Monthly Collection-2023'!AI4+'Monthly Collection-2024)'!BC4+'Monthly Collection-2025'!BC4+'Monthly Collection-2026'!BC4+'Monthly Collection-2027'!BC4+'Monthly Collection-2028'!BC4 -> 300 | I4: =IF(G4>(E4*1000*41),"Advanced",IF(G4<(E4*1000*41),"Due","Regular")) -> Regular
B5: ='Monthly Collection-2023'!B5 -> 2 | C5: ='Monthly Collection-2023'!C5 -> Saiful Islam | D5: 1816724075 | E5: ='Monthly Collection-2023'!E5 -> 2 | F5: =E5*100 -> 200 | G5: ='Monthly Collection-2023'!AH5+'Monthly Collection-2024)'!BB5+'Monthly Collection-2025'!BB5+'Monthly Collection-2026'!BB5+'Monthly Collection-2027'!BB5+'Monthly Collection-2028'!BB5 -> 82000 | H5: ='Monthly Collection-2023'!AI5+'Monthly Collection-2024)'!BC5+'Monthly Collection-2025'!BC5+'Monthly Collection-2026'!BC5+'Monthly Collection-2027'!BC5+'Monthly Collection-2028'!BC5 -> 0 | I5: =IF(G5>(E5*1000*41),"Advanced",IF(G5<(E5*1000*41),"Due","Regular")) -> Regular
B6: ='Monthly Collection-2023'!B6 -> 3 | C6: ='Monthly Collection-2023'!C6 -> Mohammad Tawhidul Islam | D6: 1846506898 | E6: ='Monthly Collection-2023'!E6 -> 2 | F6: =E6*100 -> 200 | G6: ='Monthly Collection-2023'!AH6+'Monthly Collection-2024)'!BB6+'Monthly Collection-2025'!BB6+'Monthly Collection-2026'!BB6+'Monthly Collection-2027'!BB6+'Monthly Collection-2028'!BB6 -> 82000 | H6: ='Monthly Collection-2023'!AI6+'Monthly Collection-2024)'!BC6+'Monthly Collection-2025'!BC6+'Monthly Collection-2026'!BC6+'Monthly Collection-2027'!BC6+'Monthly Collection-2028'!BC6 -> 100 | I6: =IF(G6>(E6*1000*41),"Advanced",IF(G6<(E6*1000*41),"Due","Regular")) -> Regular
B7: ='Monthly Collection-2023'!B7 -> 4 | C7: ='Monthly Collection-2023'!C7 -> Amanat Khan | D7: 966551311461 | E7: ='Monthly Collection-2023'!E7 -> 5 | F7: =E7*100 -> 500 | G7: ='Monthly Collection-2023'!AH7+'Monthly Collection-2024)'!BB7+'Monthly Collection-2025'!BB7+'Monthly Collection-2026'!BB7+'Monthly Collection-2027'!BB7+'Monthly Collection-2028'!BB7 -> 205000 | H7: ='Monthly Collection-2023'!AI7+'Monthly Collection-2024)'!BC7+'Monthly Collection-2025'!BC7+'Monthly Collection-2026'!BC7+'Monthly Collection-2027'!BC7+'Monthly Collection-2028'!BC7 -> 0 | I7: =IF(G7>(E7*1000*41),"Advanced",IF(G7<(E7*1000*41),"Due","Regular")) -> Regular
B8: ='Monthly Collection-2023'!B8 -> 5 | C8: ='Monthly Collection-2023'!C8 -> Nurunnabi Hosen Tanzid | D8: 1838848678 | E8: ='Monthly Collection-2023'!E8 -> 2 | F8: =E8*100 -> 200 | G8: ='Monthly Collection-2023'!AH8+'Monthly Collection-2024)'!BB8+'Monthly Collection-2025'!BB8+'Monthly Collection-2026'!BB8+'Monthly Collection-2027'!BB8+'Monthly Collection-2028'!BB8 -> 82000 | H8: ='Monthly Collection-2023'!AI8+'Monthly Collection-2024)'!BC8+'Monthly Collection-2025'!BC8+'Monthly Collection-2026'!BC8+'Monthly Collection-2027'!BC8+'Monthly Collection-2028'!BC8 -> 300 | I8: =IF(G8>(E8*1000*41),"Advanced",IF(G8<(E8*1000*41),"Due","Regular")) -> Regular
B9: ='Monthly Collection-2023'!B9 -> 6 | C9: ='Monthly Collection-2023'!C9 -> Jashim Uddin | D9: 966538760537 | E9: ='Monthly Collection-2023'!E9 -> 2 | F9: =E9*100 -> 200 | G9: ='Monthly Collection-2023'!AH9+'Monthly Collection-2024)'!BB9+'Monthly Collection-2025'!BB9+'Monthly Collection-2026'!BB9+'Monthly Collection-2027'!BB9+'Monthly Collection-2028'!BB9 -> 82000 | H9: ='Monthly Collection-2023'!AI9+'Monthly Collection-2024)'!BC9+'Monthly Collection-2025'!BC9+'Monthly Collection-2026'!BC9+'Monthly Collection-2027'!BC9+'Monthly Collection-2028'!BC9 -> 0 | I9: =IF(G9>(E9*1000*41),"Advanced",IF(G9<(E9*1000*41),"Due","Regular")) -> Regular
B10: ='Monthly Collection-2023'!B10 -> 7 | C10: ='Monthly Collection-2023'!C10 -> Shibu Sankar Karmaker | D10: 1885946523 | E10: ='Monthly Collection-2023'!E10 -> 2 | F10: =E10*100 -> 200 | G10: ='Monthly Collection-2023'!AH10+'Monthly Collection-2024)'!BB10+'Monthly Collection-2025'!BB10+'Monthly Collection-2026'!BB10+'Monthly Collection-2027'!BB10+'Monthly Collection-2028'!BB10 -> 82000 | H10: ='Monthly Collection-2023'!AI10+'Monthly Collection-2024)'!BC10+'Monthly Collection-2025'!BC10+'Monthly Collection-2026'!BC10+'Monthly Collection-2027'!BC10+'Monthly Collection-2028'!BC10 -> 0 | I10: =IF(G10>(E10*1000*41),"Advanced",IF(G10<(E10*1000*41),"Due","Regular")) -> Regular
B11: ='Monthly Collection-2023'!B11 -> 8 | C11: ='Monthly Collection-2023'!C11 -> Monsur | D11: 1608632799 | E11: ='Monthly Collection-2023'!E11 -> 2 | F11: =E11*100 -> 200 | G11: ='Monthly Collection-2023'!AH11+'Monthly Collection-2024)'!BB11+'Monthly Collection-2025'!BB11+'Monthly Collection-2026'!BB11+'Monthly Collection-2027'!BB11+'Monthly Collection-2028'!BB11 -> 82000 | H11: ='Monthly Collection-2023'!AI11+'Monthly Collection-2024)'!BC11+'Monthly Collection-2025'!BC11+'Monthly Collection-2026'!BC11+'Monthly Collection-2027'!BC11+'Monthly Collection-2028'!BC11 -> 0 | I11: =IF(G11>(E11*1000*41),"Advanced",IF(G11<(E11*1000*41),"Due","Regular")) -> Regular
B12: ='Monthly Collection-2023'!B12 -> 9 | C12: ='Monthly Collection-2023'!C12 -> Monjur Alam | D12: 1811938007 | E12: ='Monthly Collection-2023'!E12 -> 2 | F12: =E12*100 -> 200 | G12: ='Monthly Collection-2023'!AH12+'Monthly Collection-2024)'!BB12+'Monthly Collection-2025'!BB12+'Monthly Collection-2026'!BB12+'Monthly Collection-2027'!BB12+'Monthly Collection-2028'!BB12 -> 82000 | H12: ='Monthly Collection-2023'!AI12+'Monthly Collection-2024)'!BC12+'Monthly Collection-2025'!BC12+'Monthly Collection-2026'!BC12+'Monthly Collection-2027'!BC12+'Monthly Collection-2028'!BC12 -> 100 | I12: =IF(G12>(E12*1000*41),"Advanced",IF(G12<(E12*1000*41),"Due","Regular")) -> Regular
B13: ='Monthly Collection-2023'!B13 -> 10 | C13: ='Monthly Collection-2023'!C13 -> Rupal Kanti Karmaker | D13: 1812934934 | E13: ='Monthly Collection-2023'!E13 -> 1 | F13: =E13*100 -> 100 | G13: ='Monthly Collection-2023'!AH13+'Monthly Collection-2024)'!BB13+'Monthly Collection-2025'!BB13+'Monthly Collection-2026'!BB13+'Monthly Collection-2027'!BB13+'Monthly Collection-2028'!BB13 -> 40000 | H13: ='Monthly Collection-2023'!AI13+'Monthly Collection-2024)'!BC13+'Monthly Collection-2025'!BC13+'Monthly Collection-2026'!BC13+'Monthly Collection-2027'!BC13+'Monthly Collection-2028'!BC13 -> 100 | I13: =IF(G13>(E13*1000*41),"Advanced",IF(G13<(E13*1000*41),"Due","Regular")) -> Due
B14: ='Monthly Collection-2023'!B14 -> 11 | C14: ='Monthly Collection-2023'!C14 -> Yousof | D14: 1858217297 | E14: ='Monthly Collection-2023'!E14 -> 3 | F14: =E14*100 -> 300 | G14: ='Monthly Collection-2023'!AH14+'Monthly Collection-2024)'!BB14+'Monthly Collection-2025'!BB14+'Monthly Collection-2026'!BB14+'Monthly Collection-2027'!BB14+'Monthly Collection-2028'!BB14 -> 123000 | H14: ='Monthly Collection-2023'!AI14+'Monthly Collection-2024)'!BC14+'Monthly Collection-2025'!BC14+'Monthly Collection-2026'!BC14+'Monthly Collection-2027'!BC14+'Monthly Collection-2028'!BC14 -> 0 | I14: =IF(G14>(E14*1000*41),"Advanced",IF(G14<(E14*1000*41),"Due","Regular")) -> Regular
B15: ='Monthly Collection-2023'!B15 -> 12 | C15: ='Monthly Collection-2023'!C15 -> Arjun Kanti Karmaker | D15: 01813143128 | E15: ='Monthly Collection-2023'!E15 -> 1 | F15: =E15*100 -> 100 | G15: ='Monthly Collection-2023'!AH15+'Monthly Collection-2024)'!BB15+'Monthly Collection-2025'!BB15+'Monthly Collection-2026'!BB15+'Monthly Collection-2027'!BB15+'Monthly Collection-2028'!BB15 -> 41000 | H15: ='Monthly Collection-2023'!AI15+'Monthly Collection-2024)'!BC15+'Monthly Collection-2025'!BC15+'Monthly Collection-2026'!BC15+'Monthly Collection-2027'!BC15+'Monthly Collection-2028'!BC15 -> 0 | I15: =IF(G15>(E15*1000*41),"Advanced",IF(G15<(E15*1000*41),"Due","Regular")) -> Regular
B16: ='Monthly Collection-2023'!B16 -> 13 | C16: ='Monthly Collection-2023'!C16 -> Abdul Jabber | D16: 1814941801 | E16: ='Monthly Collection-2023'!E16 -> 2 | F16: =E16*100 -> 200 | G16: ='Monthly Collection-2023'!AH16+'Monthly Collection-2024)'!BB16+'Monthly Collection-2025'!BB16+'Monthly Collection-2026'!BB16+'Monthly Collection-2027'!BB16+'Monthly Collection-2028'!BB16 -> 82000 | H16: ='Monthly Collection-2023'!AI16+'Monthly Collection-2024)'!BC16+'Monthly Collection-2025'!BC16+'Monthly Collection-2026'!BC16+'Monthly Collection-2027'!BC16+'Monthly Collection-2028'!BC16 -> 0 | I16: =IF(G16>(E16*1000*41),"Advanced",IF(G16<(E16*1000*41),"Due","Regular")) -> Regular
B17: ='Monthly Collection-2023'!B17 -> 14 | C17: ='Monthly Collection-2023'!C17 -> Mohammad Helal Uddin | D17: 1819700976 | E17: ='Monthly Collection-2023'!E17 -> 3 | F17: =E17*100 -> 300 | G17: ='Monthly Collection-2023'!AH17+'Monthly Collection-2024)'!BB17+'Monthly Collection-2025'!BB17+'Monthly Collection-2026'!BB17+'Monthly Collection-2027'!BB17+'Monthly Collection-2028'!BB17 -> 123000 | H17: ='Monthly Collection-2023'!AI17+'Monthly Collection-2024)'!BC17+'Monthly Collection-2025'!BC17+'Monthly Collection-2026'!BC17+'Monthly Collection-2027'!BC17+'Monthly Collection-2028'!BC17 -> 0 | I17: =IF(G17>(E17*1000*41),"Advanced",IF(G17<(E17*1000*41),"Due","Regular")) -> Regular
B18: ='Monthly Collection-2023'!B18 -> 15 | C18: ='Monthly Collection-2023'!C18 -> Abul Kashem | D18: 1871777022 | E18: ='Monthly Collection-2023'!E18 -> 3 | F18: =E18*100 -> 300 | G18: ='Monthly Collection-2023'!AH18+'Monthly Collection-2024)'!BB18+'Monthly Collection-2025'!BB18+'Monthly Collection-2026'!BB18+'Monthly Collection-2027'!BB18+'Monthly Collection-2028'!BB18 -> 123000 | H18: ='Monthly Collection-2023'!AI18+'Monthly Collection-2024)'!BC18+'Monthly Collection-2025'!BC18+'Monthly Collection-2026'!BC18+'Monthly Collection-2027'!BC18+'Monthly Collection-2028'!BC18 -> 0 | I18: =IF(G18>(E18*1000*41),"Advanced",IF(G18<(E18*1000*41),"Due","Regular")) -> Regular
B19: ='Monthly Collection-2023'!B19 -> 16 | C19: ='Monthly Collection-2023'!C19 -> Uzzal Karmaker | D19: 1820016020 | E19: ='Monthly Collection-2023'!E19 -> 2 | F19: =E19*100 -> 200 | G19: ='Monthly Collection-2023'!AH19+'Monthly Collection-2024)'!BB19+'Monthly Collection-2025'!BB19+'Monthly Collection-2026'!BB19+'Monthly Collection-2027'!BB19+'Monthly Collection-2028'!BB19 -> 80000 | H19: ='Monthly Collection-2023'!AI19+'Monthly Collection-2024)'!BC19+'Monthly Collection-2025'!BC19+'Monthly Collection-2026'!BC19+'Monthly Collection-2027'!BC19+'Monthly Collection-2028'!BC19 -> 300 | I19: =IF(G19>(E19*1000*41),"Advanced",IF(G19<(E19*1000*41),"Due","Regular")) -> Due
B20: ='Monthly Collection-2023'!B20 -> 17 | C20: ='Monthly Collection-2023'!C20 -> Jahedul Islam | D20: 971562765681 | E20: ='Monthly Collection-2023'!E20 -> 2 | F20: =E20*100 -> 200 | G20: ='Monthly Collection-2023'!AH20+'Monthly Collection-2024)'!BB20+'Monthly Collection-2025'!BB20+'Monthly Collection-2026'!BB20+'Monthly Collection-2027'!BB20+'Monthly Collection-2028'!BB20 -> 82000 | H20: ='Monthly Collection-2023'!AI20+'Monthly Collection-2024)'!BC20+'Monthly Collection-2025'!BC20+'Monthly Collection-2026'!BC20+'Monthly Collection-2027'!BC20+'Monthly Collection-2028'!BC20 -> 0 | I20: =IF(G20>(E20*1000*41),"Advanced",IF(G20<(E20*1000*41),"Due","Regular")) -> Regular
B21: ='Monthly Collection-2023'!B21 -> 18 | C21: ='Monthly Collection-2023'!C21 -> Mohammad Alamgir | D21: 1822092650 | E21: ='Monthly Collection-2023'!E21 -> 2 | F21: =E21*100 -> 200 | G21: ='Monthly Collection-2023'!AH21+'Monthly Collection-2024)'!BB21+'Monthly Collection-2025'!BB21+'Monthly Collection-2026'!BB21+'Monthly Collection-2027'!BB21+'Monthly Collection-2028'!BB21 -> 86000 | H21: ='Monthly Collection-2023'!AI21+'Monthly Collection-2024)'!BC21+'Monthly Collection-2025'!BC21+'Monthly Collection-2026'!BC21+'Monthly Collection-2027'!BC21+'Monthly Collection-2028'!BC21 -> 100 | I21: =IF(G21>(E21*1000*41),"Advanced",IF(G21<(E21*1000*41),"Due","Regular")) -> Advanced
B22: ='Monthly Collection-2023'!B22 -> 19 | C22: ='Monthly Collection-2023'!C22 -> Kafil Uddin | D22: 966534770192 | E22: ='Monthly Collection-2023'!E22 -> 1 | F22: =E22*100 -> 100 | G22: ='Monthly Collection-2023'!AH22+'Monthly Collection-2024)'!BB22+'Monthly Collection-2025'!BB22+'Monthly Collection-2026'!BB22+'Monthly Collection-2027'!BB22+'Monthly Collection-2028'!BB22 -> 41000 | H22: ='Monthly Collection-2023'!AI22+'Monthly Collection-2024)'!BC22+'Monthly Collection-2025'!BC22+'Monthly Collection-2026'!BC22+'Monthly Collection-2027'!BC22+'Monthly Collection-2028'!BC22 -> 0 | I22: =IF(G22>(E22*1000*41),"Advanced",IF(G22<(E22*1000*41),"Due","Regular")) -> Regular
B23: ='Monthly Collection-2023'!B23 -> 20 | C23: ='Monthly Collection-2023'!C23 -> Mohammudul Hoque | D23: 1816821801 | E23: ='Monthly Collection-2023'!E23 -> 2 | F23: =E23*100 -> 200 | G23: ='Monthly Collection-2023'!AH23+'Monthly Collection-2024)'!BB23+'Monthly Collection-2025'!BB23+'Monthly Collection-2026'!BB23+'Monthly Collection-2027'!BB23+'Monthly Collection-2028'!BB23 -> 82000 | H23: ='Monthly Collection-2023'!AI23+'Monthly Collection-2024)'!BC23+'Monthly Collection-2025'!BC23+'Monthly Collection-2026'!BC23+'Monthly Collection-2027'!BC23+'Monthly Collection-2028'!BC23 -> 0 | I23: =IF(G23>(E23*1000*41),"Advanced",IF(G23<(E23*1000*41),"Due","Regular")) -> Regular
B24: ='Monthly Collection-2023'!B24 -> 21 | C24: ='Monthly Collection-2023'!C24 -> Nurul Amin | D24: 1820989105 | E24: ='Monthly Collection-2023'!E24 -> 1 | F24: =E24*100 -> 100 | G24: ='Monthly Collection-2023'!AH24+'Monthly Collection-2024)'!BB24+'Monthly Collection-2025'!BB24+'Monthly Collection-2026'!BB24+'Monthly Collection-2027'!BB24+'Monthly Collection-2028'!BB24 -> 41000 | H24: ='Monthly Collection-2023'!AI24+'Monthly Collection-2024)'!BC24+'Monthly Collection-2025'!BC24+'Monthly Collection-2026'!BC24+'Monthly Collection-2027'!BC24+'Monthly Collection-2028'!BC24 -> 50 | I24: =IF(G24>(E24*1000*41),"Advanced",IF(G24<(E24*1000*41),"Due","Regular")) -> Regular
B25: ='Monthly Collection-2023'!B25 -> 22 | C25: ='Monthly Collection-2023'!C25 -> Abul Kashem | D25: 1873812598 | E25: ='Monthly Collection-2023'!E25 -> 1 | F25: =E25*100 -> 100 | G25: ='Monthly Collection-2023'!AH25+'Monthly Collection-2024)'!BB25+'Monthly Collection-2025'!BB25+'Monthly Collection-2026'!BB25+'Monthly Collection-2027'!BB25+'Monthly Collection-2028'!BB25 -> 40000 | H25: ='Monthly Collection-2023'!AI25+'Monthly Collection-2024)'!BC25+'Monthly Collection-2025'!BC25+'Monthly Collection-2026'!BC25+'Monthly Collection-2027'!BC25+'Monthly Collection-2028'!BC25 -> 150 | I25: =IF(G25>(E25*1000*41),"Advanced",IF(G25<(E25*1000*41),"Due","Regular")) -> Due
B26: ='Monthly Collection-2023'!B26 -> 23 | C26: ='Monthly Collection-2023'!C26 -> Belal Uddin | D26: 1815073916 | E26: ='Monthly Collection-2023'!E26 -> 1 | F26: =E26*100 -> 100 | G26: ='Monthly Collection-2023'!AH26+'Monthly Collection-2024)'!BB26+'Monthly Collection-2025'!BB26+'Monthly Collection-2026'!BB26+'Monthly Collection-2027'!BB26+'Monthly Collection-2028'!BB26 -> 37000 | H26: ='Monthly Collection-2023'!AI26+'Monthly Collection-2024)'!BC26+'Monthly Collection-2025'!BC26+'Monthly Collection-2026'!BC26+'Monthly Collection-2027'!BC26+'Monthly Collection-2028'!BC26 -> 650 | I26: =IF(G26>(E26*1000*41),"Advanced",IF(G26<(E26*1000*41),"Due","Regular")) -> Due
B27: ='Monthly Collection-2023'!B27 -> 24 | C27: ='Monthly Collection-2023'!C27 -> Md. Helal Uddin | D27: 1860493163 | E27: ='Monthly Collection-2023'!E27 -> 1 | F27: =E27*100 -> 100 | G27: ='Monthly Collection-2023'!AH27+'Monthly Collection-2024)'!BB27+'Monthly Collection-2025'!BB27+'Monthly Collection-2026'!BB27+'Monthly Collection-2027'!BB27+'Monthly Collection-2028'!BB27 -> 36000 | H27: ='Monthly Collection-2023'!AI27+'Monthly Collection-2024)'!BC27+'Monthly Collection-2025'!BC27+'Monthly Collection-2026'!BC27+'Monthly Collection-2027'!BC27+'Monthly Collection-2028'!BC27 -> 1600 | I27: =IF(G27>(E27*1000*41),"Advanced",IF(G27<(E27*1000*41),"Due","Regular")) -> Due
... B30: ='Monthly Collection-2023'!B30 -> 27 | C30: ='Monthly Collection-2023'!C30 -> Riad Hossen | D30: 1882217274 | E30: ='Monthly Collection-2023'!E30 -> 1 | F30: =E30*100 -> 100 | G30: ='Monthly Collection-2023'!AH30+'Monthly Collection-2024)'!BB30+'Monthly Collection-2025'!BB30+'Monthly Collection-2026'!BB30+'Monthly Collection-2027'!BB30+'Monthly Collection-2028'!BB30 -> 41000 | H30: ='Monthly Collection-2023'!AI30+'Monthly Collection-2024)'!BC30+'Monthly Collection-2025'!BC30+'Monthly Collection-2026'!BC30+'Monthly Collection-2027'!BC30+'Monthly Collection-2028'!BC30 -> 100 | I30: =IF(G30>(E30*1000*41),"Advanced",IF(G30<(E30*1000*41),"Due","Regular")) -> Regular
B31: ='Monthly Collection-2023'!B31 -> 28 | C31: ='Monthly Collection-2023'!C31 -> Md. Sohel Islam | D31: 00971527120848 | E31: ='Monthly Collection-2023'!E31 -> 1 | F31: =E31*100 -> 100 | G31: ='Monthly Collection-2023'!AH31+'Monthly Collection-2024)'!BB31+'Monthly Collection-2025'!BB31+'Monthly Collection-2026'!BB31+'Monthly Collection-2027'!BB31+'Monthly Collection-2028'!BB31 -> 41000 | H31: ='Monthly Collection-2023'!AI31+'Monthly Collection-2024)'!BC31+'Monthly Collection-2025'!BC31+'Monthly Collection-2026'!BC31+'Monthly Collection-2027'!BC31+'Monthly Collection-2028'!BC31 -> 100 | I31: =IF(G31>(E31*1000*41),"Advanced",IF(G31<(E31*1000*41),"Due","Regular")) -> Regular
B32: ='Monthly Collection-2023'!B32 -> 29 | C32: ='Monthly Collection-2023'!C32 -> Idrish Alam | D32: 1883033042 | E32: ='Monthly Collection-2023'!E32 -> 1 | F32: =E32*100 -> 100 | G32: ='Monthly Collection-2023'!AH32+'Monthly Collection-2024)'!BB32+'Monthly Collection-2025'!BB32+'Monthly Collection-2026'!BB32+'Monthly Collection-2027'!BB32+'Monthly Collection-2028'!BB32 -> 41000 | H32: ='Monthly Collection-2023'!AI32+'Monthly Collection-2024)'!BC32+'Monthly Collection-2025'!BC32+'Monthly Collection-2026'!BC32+'Monthly Collection-2027'!BC32+'Monthly Collection-2028'!BC32 -> 100 | I32: =IF(G32>(E32*1000*41),"Advanced",IF(G32<(E32*1000*41),"Due","Regular")) -> Regular
B33: ='Monthly Collection-2023'!B33 -> 30 | C33: ='Monthly Collection-2023'!C33 -> Jahed | D33: 966562024068 | E33: ='Monthly Collection-2023'!E33 -> 2 | F33: =E33*100 -> 200 | G33: ='Monthly Collection-2023'!AH33+'Monthly Collection-2024)'!BB33+'Monthly Collection-2025'!BB33+'Monthly Collection-2026'!BB33+'Monthly Collection-2027'!BB33+'Monthly Collection-2028'!BB33 -> 82000 | H33: ='Monthly Collection-2023'!AI33+'Monthly Collection-2024)'!BC33+'Monthly Collection-2025'!BC33+'Monthly Collection-2026'!BC33+'Monthly Collection-2027'!BC33+'Monthly Collection-2028'!BC33 -> 300 | I33: =IF(G33>(E33*1000*41),"Advanced",IF(G33<(E33*1000*41),"Due","Regular")) -> Regular
B34: ='Monthly Collection-2023'!B34 -> 31 | C34: ='Monthly Collection-2023'!C34 -> Sahidul Islam | D34: 966549955548 | E34: ='Monthly Collection-2023'!E34 -> 2 | F34: =E34*100 -> 200 | G34: ='Monthly Collection-2023'!AH34+'Monthly Collection-2024)'!BB34+'Monthly Collection-2025'!BB34+'Monthly Collection-2026'!BB34+'Monthly Collection-2027'!BB34+'Monthly Collection-2028'!BB34 -> 82000 | H34: ='Monthly Collection-2023'!AI34+'Monthly Collection-2024)'!BC34+'Monthly Collection-2025'!BC34+'Monthly Collection-2026'!BC34+'Monthly Collection-2027'!BC34+'Monthly Collection-2028'!BC34 -> 100 | I34: =IF(G34>(E34*1000*41),"Advanced",IF(G34<(E34*1000*41),"Due","Regular")) -> Regular
B35: ='Monthly Collection-2023'!B35 -> 32 | C35: ='Monthly Collection-2023'!C35 -> Md. Sohel Uddin | D35: 1822020050 | E35: ='Monthly Collection-2023'!E35 -> 2 | F35: =E35*100 -> 200 | G35: ='Monthly Collection-2023'!AH35+'Monthly Collection-2024)'!BB35+'Monthly Collection-2025'!BB35+'Monthly Collection-2026'!BB35+'Monthly Collection-2027'!BB35+'Monthly Collection-2028'!BB35 -> 82000 | H35: ='Monthly Collection-2023'!AI35+'Monthly Collection-2024)'!BC35+'Monthly Collection-2025'!BC35+'Monthly Collection-2026'!BC35+'Monthly Collection-2027'!BC35+'Monthly Collection-2028'!BC35 -> 900 | I35: =IF(G35>(E35*1000*41),"Advanced",IF(G35<(E35*1000*41),"Due","Regular")) -> Regular
B36: ='Monthly Collection-2023'!B36 -> 33 | C36: ='Monthly Collection-2023'!C36 -> Mohammad Faruk | D36: 1831797810 | E36: ='Monthly Collection-2023'!E36 -> 1 | F36: =E36*100 -> 100 | G36: ='Monthly Collection-2023'!AH36+'Monthly Collection-2024)'!BB36+'Monthly Collection-2025'!BB36+'Monthly Collection-2026'!BB36+'Monthly Collection-2027'!BB36+'Monthly Collection-2028'!BB36 -> 39000 | H36: ='Monthly Collection-2023'!AI36+'Monthly Collection-2024)'!BC36+'Monthly Collection-2025'!BC36+'Monthly Collection-2026'!BC36+'Monthly Collection-2027'!BC36+'Monthly Collection-2028'!BC36 -> 650 | I36: =IF(G36>(E36*1000*41),"Advanced",IF(G36<(E36*1000*41),"Due","Regular")) -> Due
B37: ='Monthly Collection-2023'!B37 -> 34 | C37: ='Monthly Collection-2023'!C37 -> Didarul Islam | D37: 971562663270 | E37: ='Monthly Collection-2023'!E37 -> 1 | F37: =E37*100 -> 100 | G37: ='Monthly Collection-2023'!AH37+'Monthly Collection-2024)'!BB37+'Monthly Collection-2025'!BB37+'Monthly Collection-2026'!BB37+'Monthly Collection-2027'!BB37+'Monthly Collection-2028'!BB37 -> 41000 | H37: ='Monthly Collection-2023'!AI37+'Monthly Collection-2024)'!BC37+'Monthly Collection-2025'!BC37+'Monthly Collection-2026'!BC37+'Monthly Collection-2027'!BC37+'Monthly Collection-2028'!BC37 -> 0 | I37: =IF(G37>(E37*1000*41),"Advanced",IF(G37<(E37*1000*41),"Due","Regular")) -> Regular
B38: ='Monthly Collection-2023'!B38 -> 35 | C38: ='Monthly Collection-2023'!C38 -> Mohammad Fahim | D38: 1873808231 | E38: ='Monthly Collection-2023'!E38 -> 2 | F38: =E38*100 -> 200 | G38: ='Monthly Collection-2023'!AH38+'Monthly Collection-2024)'!BB38+'Monthly Collection-2025'!BB38+'Monthly Collection-2026'!BB38+'Monthly Collection-2027'!BB38+'Monthly Collection-2028'!BB38 -> 82000 | H38: ='Monthly Collection-2023'!AI38+'Monthly Collection-2024)'!BC38+'Monthly Collection-2025'!BC38+'Monthly Collection-2026'!BC38+'Monthly Collection-2027'!BC38+'Monthly Collection-2028'!BC38 -> 0 | I38: =IF(G38>(E38*1000*41),"Advanced",IF(G38<(E38*1000*41),"Due","Regular")) -> Regular
B39: ='Monthly Collection-2023'!B39 -> 36 | C39: ='Monthly Collection-2023'!C39 -> Delower Hossain | D39: 971561572487 | E39: ='Monthly Collection-2023'!E39 -> 1 | F39: =E39*100 -> 100 | G39: ='Monthly Collection-2023'!AH39+'Monthly Collection-2024)'!BB39+'Monthly Collection-2025'!BB39+'Monthly Collection-2026'!BB39+'Monthly Collection-2027'!BB39+'Monthly Collection-2028'!BB39 -> 41000 | H39: ='Monthly Collection-2023'!AI39+'Monthly Collection-2024)'!BC39+'Monthly Collection-2025'!BC39+'Monthly Collection-2026'!BC39+'Monthly Collection-2027'!BC39+'Monthly Collection-2028'!BC39 -> 0 | I39: =IF(G39>(E39*1000*41),"Advanced",IF(G39<(E39*1000*41),"Due","Regular")) -> Regular
B40: ='Monthly Collection-2023'!B40 -> 37 | C40: ='Monthly Collection-2023'!C40 -> Abdul Malek | D40: 1879352117 | E40: ='Monthly Collection-2023'!E40 -> 2 | F40: =E40*100 -> 200 | G40: ='Monthly Collection-2023'!AH40+'Monthly Collection-2024)'!BB40+'Monthly Collection-2025'!BB40+'Monthly Collection-2026'!BB40+'Monthly Collection-2027'!BB40+'Monthly Collection-2028'!BB40 -> 82000 | H40: ='Monthly Collection-2023'!AI40+'Monthly Collection-2024)'!BC40+'Monthly Collection-2025'!BC40+'Monthly Collection-2026'!BC40+'Monthly Collection-2027'!BC40+'Monthly Collection-2028'!BC40 -> 100 | I40: =IF(G40>(E40*1000*41),"Advanced",IF(G40<(E40*1000*41),"Due","Regular")) -> Regular
B41: ='Monthly Collection-2023'!B41 -> 38 | C41: ='Monthly Collection-2023'!C41 -> Khalil Uddin | D41: 00971569173725 | E41: ='Monthly Collection-2023'!E41 -> 2 | F41: =E41*100 -> 200 | G41: ='Monthly Collection-2023'!AH41+'Monthly Collection-2024)'!BB41+'Monthly Collection-2025'!BB41+'Monthly Collection-2026'!BB41+'Monthly Collection-2027'!BB41+'Monthly Collection-2028'!BB41 -> 82000 | H41: ='Monthly Collection-2023'!AI41+'Monthly Collection-2024)'!BC41+'Monthly Collection-2025'!BC41+'Monthly Collection-2026'!BC41+'Monthly Collection-2027'!BC41+'Monthly Collection-2028'!BC41 -> 0 | I41: =IF(G41>(E41*1000*41),"Advanced",IF(G41<(E41*1000*41),"Due","Regular")) -> Regular
B42: ='Monthly Collection-2023'!B42 -> 39 | C42: ='Monthly Collection-2023'!C42 -> Mohammad Abul Hashem | D42: 1873807617 | E42: ='Monthly Collection-2023'!E42 -> 2 | F42: =E42*100 -> 200 | G42: ='Monthly Collection-2023'!AH42+'Monthly Collection-2024)'!BB42+'Monthly Collection-2025'!BB42+'Monthly Collection-2026'!BB42+'Monthly Collection-2027'!BB42+'Monthly Collection-2028'!BB42 -> 76000 | H42: ='Monthly Collection-2023'!AI42+'Monthly Collection-2024)'!BC42+'Monthly Collection-2025'!BC42+'Monthly Collection-2026'!BC42+'Monthly Collection-2027'!BC42+'Monthly Collection-2028'!BC42 -> 1400 | I42: =IF(G42>(E42*1000*41),"Advanced",IF(G42<(E42*1000*41),"Due","Regular")) -> Due
...

Sheet Month Wise Collection Summary
A1: =HYPERLINK("#DASHBOARD!A1","⬅ Dashboard") -> ⬅ Dashboard
B2: Lohagara Progoti Youth Organization Kamar Pukur Par, Uzir Hat, Lohagara, Chittagong.
B3: Month | C3: Regular Deposit | D3: Advance | E3: Due Collection | F3: Fine | G3: CNG & Other Installment Collection | H3: Expense | I3: Bank Deposit
B4: 45078 | C4: ='Monthly Collection-2023'!F81 -> 124000 | D4: ='Monthly Collection-2023'!G81 -> 0 | E4: ='Monthly Collection-2023'!H81 -> 0 | F4: ='Monthly Collection-2023'!I81 -> 0 | H4: ='Month Wise Expenses'!D9 -> 6400 | I4: =SUM(C4:G4)-H4 -> 117600
B5: 45108 | C5: ='Monthly Collection-2023'!J81 -> 124000 | D5: ='Monthly Collection-2023'!K81 -> 4000 | E5: ='Monthly Collection-2023'!L81 -> 0 | F5: ='Monthly Collection-2023'!M81 -> 0 | H5: ='Month Wise Expenses'!D10 -> 300 | I5: =SUM(C5:G5)-H5 -> 127700
B6: 45139 | C6: ='Monthly Collection-2023'!N81 -> 122000 | D6: ='Monthly Collection-2023'!O81 -> 0 | E6: ='Monthly Collection-2023'!P81 -> 0 | F6: ='Monthly Collection-2023'!Q81 -> 50 | H6: ='Month Wise Expenses'!D11 -> 0 | I6: =SUM(C6:G6)-H6 -> 122050
B7: 45170 | C7: ='Monthly Collection-2023'!R81 -> 118000 | D7: ='Monthly Collection-2023'!S81 -> 11000 | E7: ='Monthly Collection-2023'!T81 -> 1000 | F7: ='Monthly Collection-2023'!U81 -> 200 | H7: ='Month Wise Expenses'!D12 -> 0 | I7: =SUM(C7:G7)-H7 -> 130200
B8: 45200 | C8: ='Monthly Collection-2023'!V81 -> 109000 | D8: ='Monthly Collection-2023'!W81 -> 0 | E8: ='Monthly Collection-2023'!X81 -> 5000 | F8: ='Monthly Collection-2023'!Y81 -> 300 | H8: ='Month Wise Expenses'!D13 -> 0 | I8: =SUM(C8:G8)-H8 -> 114300
B9: 45231 | C9: ='Monthly Collection-2023'!Z81 -> 108000 | D9: ='Monthly Collection-2023'!AA81 -> 0 | E9: ='Monthly Collection-2023'!AB81 -> 7000 | F9: ='Monthly Collection-2023'!AC81 -> 350 | H9: ='Month Wise Expenses'!D14 -> 0 | I9: =SUM(C9:G9)-H9 -> 115350
B10: 45261 | C10: ='Monthly Collection-2023'!AD81 -> 108000 | D10: ='Monthly Collection-2023'!AE81 -> 11000 | E10: ='Monthly Collection-2023'!AF81 -> 10000 | F10: ='Monthly Collection-2023'!AG81 -> 500 | H10: ='Month Wise Expenses'!D15 -> 0 | I10: =SUM(C10:G10)-H10 -> 129500
B11: 2023 Total | C11: =SUM(C4:C10) -> 813000 | D11: =SUM(D4:D10) -> 26000 | E11: =SUM(E4:E10) -> 23000 | F11: =SUM(F4:F10) -> 1400 | G11: =SUM(G4:G10) -> 0 | H11: =SUM(H4:H10) -> 6700 | I11: =SUM(I4:I10) -> 856700
B12: 45292 | C12: ='Monthly Collection-2024)'!F81 -> 112000 | D12: ='Monthly Collection-2024)'!G81 -> 0 | E12: ='Monthly Collection-2024)'!H81 -> 11000 | F12: ='Monthly Collection-2024)'!I81 -> 550 | H12: ='Month Wise Expenses'!G4 -> 0 | I12: =SUM(C12:G12)-H12 -> 123550
B13: 45323 | C13: ='Monthly Collection-2024)'!J81 -> 116000 | D13: ='Monthly Collection-2024)'!K81 -> 0 | E13: ='Monthly Collection-2024)'!L81 -> 2000 | F13: ='Monthly Collection-2024)'!M81 -> 100 | H13: ='Month Wise Expenses'!G5 -> 0 | I13: =SUM(C13:G13)-H13 -> 118100
B14: 45352 | C14: ='Monthly Collection-2024)'!N81 -> 119000 | D14: ='Monthly Collection-2024)'!O81 -> 11000 | E14: ='Monthly Collection-2024)'!P81 -> 3000 | F14: ='Monthly Collection-2024)'!Q81 -> 200 | H14: ='Month Wise Expenses'!G6 -> 0 | I14: =SUM(C14:G14)-H14 -> 133200
B15: 45383 | C15: ='Monthly Collection-2024)'!R81 -> 108000 | D15: ='Monthly Collection-2024)'!S81 -> 0 | E15: ='Monthly Collection-2024)'!T81 -> 2000 | F15: ='Monthly Collection-2024)'!U81 -> 200 | H15: ='Month Wise Expenses'!G7 -> 0 | I15: =SUM(C15:G15)-H15 -> 110200
B16: 45413 | C16: ='Monthly Collection-2024)'!V81 -> 104000 | D16: ='Monthly Collection-2024)'!W81 -> 4000 | E16: ='Monthly Collection-2024)'!X81 -> 32000 | F16: ='Monthly Collection-2024)'!Y81 -> 3800 | H16: ='Month Wise Expenses'!G8 -> 0 | I16: =SUM(C16:G16)-H16 -> 143800
B17: 45444 | C17: ='Monthly Collection-2024)'!Z81 -> 115000 | D17: ='Monthly Collection-2024)'!AA81 -> 6000 | E17: ='Monthly Collection-2024)'!AB81 -> 12000 | F17: ='Monthly Collection-2024)'!AC81 -> 600 | H17: ='Month Wise Expenses'!G9 -> 0 | I17: =SUM(C17:G17)-H17 -> 133600
B18: 45474 | C18: ='Monthly Collection-2024)'!AD81 -> 114000 | D18: ='Monthly Collection-2024)'!AE81 -> 11000 | E18: ='Monthly Collection-2024)'!AF81 -> 8000 | F18: ='Monthly Collection-2024)'!AG81 -> 550 | H18: ='Month Wise Expenses'!G10 -> 0 | I18: =SUM(C18:G18)-H18 -> 133550
B19: 45505 | C19: ='Monthly Collection-2024)'!AH81 -> 108000 | D19: ='Monthly Collection-2024)'!AI81 -> 8000 | E19: ='Monthly Collection-2024)'!AJ81 -> 8000 | F19: ='Monthly Collection-2024)'!AK81 -> 1350 | H19: ='Month Wise Expenses'!G11 -> 0 | I19: =SUM(C19:G19)-H19 -> 125350
B20: 45536 | C20: ='Monthly Collection-2024)'!AL81 -> 108000 | D20: ='Monthly Collection-2024)'!AM81 -> 3000 | E20: ='Monthly Collection-2024)'!AN81 -> 7000 | F20: ='Monthly Collection-2024)'!AO81 -> 400 | H20: ='Month Wise Expenses'!G12 -> 1000 | I20: =SUM(C20:G20)-H20 -> 117400
B21: 45566 | C21: ='Monthly Collection-2024)'!AP81 -> 109000 | D21: ='Monthly Collection-2024)'!AQ81 -> 6000 | E21: ='Monthly Collection-2024)'!AR81 -> 5000 | F21: ='Monthly Collection-2024)'!AS81 -> 250 | H21: ='Month Wise Expenses'!G13 -> 1000 | I21: =SUM(C21:G21)-H21 -> 119250
B22: 45597 | C22: ='Monthly Collection-2024)'!AT81 -> 111000 | D22: ='Monthly Collection-2024)'!AU81 -> 2000 | E22: ='Monthly Collection-2024)'!AV81 -> 14000 | F22: ='Monthly Collection-2024)'!AW81 -> 700 | H22: ='Month Wise Expenses'!G14 -> 1300 | I22: =SUM(C22:G22)-H22 -> 126400
B23: 45627 | C23: ='Monthly Collection-2024)'!AX81 -> 105000 | D23: ='Monthly Collection-2024)'!AY81 -> 8000 | E23: ='Monthly Collection-2024)'!AZ81 -> 4000 | F23: ='Monthly Collection-2024)'!BA81 -> 200 | H23: ='Month Wise Expenses'!G15 -> 1000 | I23: =SUM(C23:G23)-H23 -> 116200
B24: 2024 Total | C24: =SUM(C12:C23) -> 1329000 | D24: =SUM(D12:D23) -> 59000 | E24: =SUM(E12:E23) -> 108000 | F24: =SUM(F12:F23) -> 8900 | G24: =SUM(G12:G23) -> 0 | H24: =SUM(H12:H23) -> 4300 | I24: =SUM(I12:I23) -> 1500600
B25: 45658 | C25: ='Monthly Collection-2025'!F81 -> 113000 | D25: ='Monthly Collection-2025'!G81 -> 14000 | E25: ='Monthly Collection-2025'!H81 -> 20000 | F25: ='Monthly Collection-2025'!I81 -> 1000 | G25: ='Month Wise CNG Instlmnt Summary'!C4 -> 30000 | H25: ='Month Wise Expenses'!J4 -> 1000 | I25: =SUM(C25:G25)-H25 -> 177000
B26: 45689 | C26: ='Monthly Collection-2025'!J81 -> 113000 | D26: ='Monthly Collection-2025'!K81 -> 2000 | E26: ='Monthly Collection-2025'!L81 -> 12000 | F26: ='Monthly Collection-2025'!M81 -> 750 | G26: ='Month Wise CNG Instlmnt Summary'!C5 -> 30000 | H26: ='Month Wise Expenses'!J5 -> 1250 | I26: =SUM(C26:G26)-H26 -> 156500
B27: 45717 | C27: ='Monthly Collection-2025'!N81 -> 108000 | D27: ='Monthly Collection-2025'!O81 -> 4000 | E27: ='Monthly Collection-2025'!P81 -> 3000 | F27: ='Monthly Collection-2025'!Q81 -> 150 | G27: ='Month Wise CNG Instlmnt Summary'!C6 -> 45000 | H27: ='Month Wise Expenses'!J6 -> 1400 | I27: =SUM(C27:G27)-H27 -> 158750
B28: 45748 | C28: ='Monthly Collection-2025'!R81 -> 104000 | D28: ='Monthly Collection-2025'!S81 -> 5000 | E28: ='Monthly Collection-2025'!T81 -> 10000 | F28: ='Monthly Collection-2025'!U81 -> 500 | G28: ='Month Wise CNG Instlmnt Summary'!C7 -> 45000 | H28: ='Month Wise Expenses'!J7 -> 1000 | I28: =SUM(C28:G28)-H28 -> 163500
B29: 45778 | C29: ='Monthly Collection-2025'!V81 -> 108000 | D29: ='Monthly Collection-2025'!W81 -> 8000 | E29: ='Monthly Collection-2025'!X81 -> 18000 | F29: ='Monthly Collection-2025'!Y81 -> 950 | G29: ='Month Wise CNG Instlmnt Summary'!C8 -> 55000 | H29: ='Month Wise Expenses'!J8 -> 1000 | I29: =SUM(C29:G29)-H29 -> 188950
B30: 45809 | C30: ='Monthly Collection-2025'!Z81 -> 107000 | D30: ='Monthly Collection-2025'!AA81 -> 5000 | E30: ='Monthly Collection-2025'!AB81 -> 7000 | F30: ='Monthly Collection-2025'!AC81 -> 350 | G30: ='Month Wise CNG Instlmnt Summary'!C9 -> 40000 | H30: ='Month Wise Expenses'!J9 -> 1000 | I30: =SUM(C30:G30)-H30 -> 158350
B31: 45839 | C31: ='Monthly Collection-2025'!AD81 -> 102000 | D31: ='Monthly Collection-2025'!AE81 -> 12000 | E31: ='Monthly Collection-2025'!AF81 -> 9000 | F31: ='Monthly Collection-2025'!AG81 -> 450 | G31: ='Month Wise CNG Instlmnt Summary'!C10 -> 55000 | H31: ='Month Wise Expenses'!J10 -> 1250 | I31: =SUM(C31:G31)-H31 -> 177200
B32: 45870 | C32: ='Monthly Collection-2025'!AH81 -> 108000 | D32: ='Monthly Collection-2025'!AI81 -> 2000 | E32: ='Monthly Collection-2025'!AJ81 -> 24000 | F32: ='Monthly Collection-2025'!AK81 -> 1250 | G32: ='Month Wise CNG Instlmnt Summary'!C11 -> 55000 | H32: ='Month Wise Expenses'!J11 -> 4000 | I32: =SUM(C32:G32)-H32 -> 186250
B33: 45901 | C33: ='Monthly Collection-2025'!AL81 -> 105000 | D33: ='Monthly Collection-2025'!AM81 -> 10000 | E33: ='Monthly Collection-2025'!AN81 -> 3000 | F33: ='Monthly Collection-2025'!AO81 -> 150 | G33: ='Month Wise CNG Instlmnt Summary'!C12+2700 -> 57700 | H33: ='Month Wise Expenses'!J12 -> 3250 | I33: =SUM(C33:G33)-H33 -> 172600
B34: 45931 | C34: ='Monthly Collection-2025'!AP81 -> 108000 | D34: ='Monthly Collection-2025'!AQ81 -> 3000 | E34: ='Monthly Collection-2025'!AR81 -> 11000 | F34: ='Monthly Collection-2025'!AS81 -> 900 | G34: ='Month Wise CNG Instlmnt Summary'!C13 -> 55000 | H34: ='Month Wise Expenses'!J13 -> 1250 | I34: =SUM(C34:G34)-H34 -> 176650
B35: 45962 | C35: ='Monthly Collection-2025'!AT81 -> 114000 | D35: ='Monthly Collection-2025'!AU81 -> 5000 | E35: ='Monthly Collection-2025'!AV81 -> 11000 | F35: ='Monthly Collection-2025'!AW81 -> 550 | G35: ='Month Wise CNG Instlmnt Summary'!C14+27000 -> 93000 | H35: ='Month Wise Expenses'!J14 -> 1000 | I35: =SUM(C35:G35)-H35 -> 222550
B36: 45992 | C36: ='Monthly Collection-2025'!AX81 -> 109000 | D36: ='Monthly Collection-2025'!AY81 -> 0 | E36: ='Monthly Collection-2025'!AZ81 -> 10000 | F36: ='Monthly Collection-2025'!BA81 -> 500 | G36: ='Month Wise CNG Instlmnt Summary'!C15 -> 72000 | H36: ='Month Wise Expenses'!J15 -> 1000 | I36: =SUM(C36:G36)-H36 -> 190500
B37: 2025 Total | C37: =SUM(C25:C36) -> 1299000 | D37: =SUM(D25:D36) -> 70000 | E37: =SUM(E25:E36) -> 138000 | F37: =SUM(F25:F36) -> 7500 | G37: =SUM(G25:G36) -> 632700 | H37: =SUM(H25:H36) -> 18400 | I37: =SUM(I25:I36) -> 2128800
B38: 46023 | C38: ='Monthly Collection-2026'!F81 -> 114000 | D38: ='Monthly Collection-2026'!G81 -> 8000 | E38: ='Monthly Collection-2026'!H81 -> 3000 | F38: ='Monthly Collection-2026'!I81 -> 150 | G38: ='Month Wise CNG Instlmnt Summary'!F4 -> 66000 | H38: ='Month Wise Expenses'!M4 -> 50697 | I38: =SUM(C38:G38)-H38 -> 140453
B39: 46054 | C39: ='Monthly Collection-2026'!J81 -> 105000 | D39: ='Monthly Collection-2026'!K81 -> 4000 | E39: ='Monthly Collection-2026'!L81 -> 10000 | F39: ='Monthly Collection-2026'!M81 -> 500 | G39: ='Month Wise CNG Instlmnt Summary'!F5 -> 73000 | H39: ='Month Wise Expenses'!M5 -> 1000 | I39: =SUM(C39:G39)-H39 -> 191500
B40: 46082 | C40: ='Monthly Collection-2026'!N81 -> 106000 | D40: ='Monthly Collection-2026'!O81 -> 12000 | E40: ='Monthly Collection-2026'!P81 -> 8000 | F40: ='Monthly Collection-2026'!Q81 -> 400 | G40: ='Month Wise CNG Instlmnt Summary'!F6 -> 55000 | H40: ='Month Wise Expenses'!M6 -> 1000 | I40: =SUM(C40:G40)-H40 -> 180400
...

Sheet Month Wise Expenses
A1: =HYPERLINK("#DASHBOARD!A1","⬅ Dashboard") -> ⬅ Dashboard
B2: 2023 | E2: 2024 | H2: 2025 | K2: 2026 | N2: 2027 | Q2: 2028
B3: Month | C3: Description | D3: Expenses | E3: Month | F3: Description | G3: Expenses | H3: Month | I3: Description | J3: Expenses | K3: Month | L3: Description | M3: Expenses | N3: Month | O3: Description | P3: Expenses | Q3: Month | R3: Description | S3: Expenses
E4: January | F4: Expense | G4: 0 | H4: January | I4: Cashier Salary | J4: 1000 | K4: January | L4: Picnic Expense & Cashier Salary | M4: =1200+48570+927 -> 50697 | N4: January | Q4: January
E5: February | F5: Expense | G5: 0 | H5: February | I5: Cashier Salary & Other | J5: 1250 | K5: February | L5: Cashier Salary | M5: 1000 | N5: February | Q5: February
E6: March | F6: Expense | G6: 0 | H6: March | I6: Cashier Salary & Other | J6: 1400 | K6: March | L6: Cashier Salary | M6: 1000 | N6: March | Q6: March
E7: April | F7: Expense | G7: 0 | H7: April | I7: Cashier Salary | J7: 1000 | K7: April | L7: Print Cost | M7: 100 | N7: April | Q7: April
E8: May | F8: Expense | G8: 0 | H8: May | I8: Cashier Salary | J8: 1000 | K8: May | L8: Form Print & Snacks | M8: 200 | N8: May | Q8: May
B9: June | C9: Cash Memmo Book & Money Receipt Book Print | D9: 6400 | E9: June | F9: Expense | G9: 0 | H9: June | I9: Cashier Salary | J9: 1000 | K9: June | L9: Snacks | M9: 100 | N9: June
B10: July | C10: Snacks & Others | D10: 300 | E10: July | F10: Expense | G10: 0 | H10: July | I10: Cashier Salary & Other | J10: 1250 | K10: July | L10: Expense | M10: 0 | N10: July
B11: August | C11: Expense | D11: 0 | E11: August | F11: Expense | G11: 0 | H11: August | I11: Cashier Salary & Cabinet Purchase | J11: 4000 | K11: August | L11: Snacks | M11: 100 | N11: August
B12: September | C12: Expense | D12: 0 | E12: September | F12: Cashier Salary | G12: 1000 | H12: September | I12: Cashier Salary & Chair Purchase | J12: 3250 | K12: September | L12: Form Print & Snacks | M12: 200 | N12: September
B13: October | C13: Expense | D13: 0 | E13: October | F13: Cashier Salary | G13: 1000 | H13: October | I13: Cashier Salary & Other | J13: 1250 | K13: October | L13: Snacks & Bank SMS Charge | M13: =100+172.83 -> 272.83 | N13: October
B14: November | C14: Expense | D14: 0 | E14: November | F14: Cashier Salary & Other | G14: 1300 | H14: November | I14: Cashier Salary | J14: 1000 | K14: November | N14: November
B15: December | C15: Expense | D15: 0 | E15: December | F15: Cashier Salary | G15: 1000 | H15: December | I15: Cashier Salary | J15: 1000 | K15: December | N15: December
B16: Total | D16: =SUM(D4:D15) -> 6700 | G16: =SUM(G4:G15) -> 4300 | J16: =SUM(J4:J15) -> 18400 | M16: =SUM(M4:M15) -> 53669.83 | P16: =SUM(P4:P15) -> 0 | S16: =SUM(S4:S15) -> 0

Sheet Monthly Collection-2023
A1: =HYPERLINK("#DASHBOARD!A1","⬅ Dashboard") -> ⬅ Dashboard | AK1: AUTO HELPER (do not edit): Status R=Due, G=Advance-covered; Advance balance carried month to month. Use the [+] above to expand.
B2: Member ID. | C2: Name | D2: Mobile Number | E2: Number of Shares | F2: 45078 | J2: =EDATE($F2,1) -> 45108 | N2: =EDATE($F2,2) -> 45139 | R2: =EDATE($F2,3) -> 45170 | V2: =EDATE($F2,4) -> 45200 | Z2: =EDATE($F2,5) -> 45231 | AD2: =EDATE($F2,6) -> 45261 | AH2: Total Deposit | AI2: Total Fine | AL2: =F$2 -> 45078 | AN2: =J$2 -> 45108 | AP2: =N$2 -> 45139 | AR2: =R$2 -> 45170 | AT2: =V$2 -> 45200 | AV2: =Z$2 -> 45231 | AX2: =AD$2 -> 45261
F3: Regular Deposit | G3: Advance | H3: Due Collection | I3: Fine | J3: Regular Deposit | K3: Advance | L3: Due Collection | M3: Fine | N3: Regular Deposit | O3: Advance | P3: Due Collection | Q3: Fine | R3: Regular Deposit | S3: Advance | T3: Due Collection | U3: Fine | V3: Regular Deposit | W3: Advance | X3: Due Collection | Y3: Fine | Z3: Regular Deposit | AA3: Advance | AB3: Due Collection | AC3: Fine | AD3: Regular Deposit | AE3: Advance | AF3: Due Collection | AG3: Fine | AK3: Carry-in adv | AL3: Status | AM3: Adv balance | AN3: Status | AO3: Adv balance | AP3: Status | AQ3: Adv balance | AR3: Status | AS3: Adv balance | AT3: Status | AU3: Adv balance | AV3: Status | AW3: Adv balance | AX3: Status | AY3: Adv balance
B4: =ROW()-3 -> 1 | C4: Monjurul Islam | D4: ='Member Wise Deposit Summary'!D4 -> 1814824030 | E4: 3 | F4: =$E4*1000 -> 3000 | J4: =$E4*1000 -> 3000 | N4: =$E4*1000 -> 3000 | R4: =$E4*1000 -> 3000 | V4: =$E4*1000 -> 3000 | AD4: 3000 | AF4: 3000 | AG4: 150 | AH4: =F4+G4+H4+J4+K4+L4+N4+O4+P4+R4+S4+T4+V4+W4+X4+Z4+AA4+AB4+AD4+AE4+AF4 -> 21000 | AI4: =I4+M4+Q4+U4+Y4+AC4+AG4 -> 150 | AK4: 0 | AL4: =IF(N(F4)>=$E4*1000,"",IF(AND($E4>0,AK4>=$E4*1000),"G",IF(F$2<=TODAY(),"R",""))) | AM4: =AK4-IF(AL4="G",$E4*1000,0)+N(G4) -> 0 | AN4: =IF(N(J4)>=$E4*1000,"",IF(AND($E4>0,AM4>=$E4*1000),"G",IF(J$2<=TODAY(),"R",""))) | AO4: =AM4-IF(AN4="G",$E4*1000,0)+N(K4) -> 0 | AP4: =IF(N(N4)>=$E4*1000,"",IF(AND($E4>0,AO4>=$E4*1000),"G",IF(N$2<=TODAY(),"R",""))) | AQ4: =AO4-IF(AP4="G",$E4*1000,0)+N(O4) -> 0 | AR4: =IF(N(R4)>=$E4*1000,"",IF(AND($E4>0,AQ4>=$E4*1000),"G",IF(R$2<=TODAY(),"R",""))) | AS4: =AQ4-IF(AR4="G",$E4*1000,0)+N(S4) -> 0 | AT4: =IF(N(V4)>=$E4*1000,"",IF(AND($E4>0,AS4>=$E4*1000),"G",IF(V$2<=TODAY(),"R",""))) | AU4: =AS4-IF(AT4="G",$E4*1000,0)+N(W4) -> 0 | AV4: =IF(N(Z4)>=$E4*1000,"",IF(AND($E4>0,AU4>=$E4*1000),"G",IF(Z$2<=TODAY(),"R",""))) -> R | AW4: =AU4-IF(AV4="G",$E4*1000,0)+N(AA4) -> 0 | AX4: =IF(N(AD4)>=$E4*1000,"",IF(AND($E4>0,AW4>=$E4*1000),"G",IF(AD$2<=TODAY(),"R",""))) | AY4: =AW4-IF(AX4="G",$E4*1000,0)+N(AE4) -> 0
B5: =ROW()-3 -> 2 | C5: Saiful Islam | D5: ='Member Wise Deposit Summary'!D5 -> 1816724075 | E5: 2 | F5: =$E5*1000 -> 2000 | J5: =$E5*1000 -> 2000 | N5: =$E5*1000 -> 2000 | R5: =$E5*1000 -> 2000 | V5: =$E5*1000 -> 2000 | Z5: =$E5*1000 -> 2000 | AD5: =$E5*1000 -> 2000 | AH5: =F5+G5+H5+J5+K5+L5+N5+O5+P5+R5+S5+T5+V5+W5+X5+Z5+AA5+AB5+AD5+AE5+AF5 -> 14000 | AI5: =I5+M5+Q5+U5+Y5+AC5+AG5 -> 0 | AK5: 0 | AL5: =IF(N(F5)>=$E5*1000,"",IF(AND($E5>0,AK5>=$E5*1000),"G",IF(F$2<=TODAY(),"R",""))) | AM5: =AK5-IF(AL5="G",$E5*1000,0)+N(G5) -> 0 | AN5: =IF(N(J5)>=$E5*1000,"",IF(AND($E5>0,AM5>=$E5*1000),"G",IF(J$2<=TODAY(),"R",""))) | AO5: =AM5-IF(AN5="G",$E5*1000,0)+N(K5) -> 0 | AP5: =IF(N(N5)>=$E5*1000,"",IF(AND($E5>0,AO5>=$E5*1000),"G",IF(N$2<=TODAY(),"R",""))) | AQ5: =AO5-IF(AP5="G",$E5*1000,0)+N(O5) -> 0 | AR5: =IF(N(R5)>=$E5*1000,"",IF(AND($E5>0,AQ5>=$E5*1000),"G",IF(R$2<=TODAY(),"R",""))) | AS5: =AQ5-IF(AR5="G",$E5*1000,0)+N(S5) -> 0 | AT5: =IF(N(V5)>=$E5*1000,"",IF(AND($E5>0,AS5>=$E5*1000),"G",IF(V$2<=TODAY(),"R",""))) | AU5: =AS5-IF(AT5="G",$E5*1000,0)+N(W5) -> 0 | AV5: =IF(N(Z5)>=$E5*1000,"",IF(AND($E5>0,AU5>=$E5*1000),"G",IF(Z$2<=TODAY(),"R",""))) | AW5: =AU5-IF(AV5="G",$E5*1000,0)+N(AA5) -> 0 | AX5: =IF(N(AD5)>=$E5*1000,"",IF(AND($E5>0,AW5>=$E5*1000),"G",IF(AD$2<=TODAY(),"R",""))) | AY5: =AW5-IF(AX5="G",$E5*1000,0)+N(AE5) -> 0
B6: =ROW()-3 -> 3 | C6: Mohammad Tawhidul Islam | D6: ='Member Wise Deposit Summary'!D6 -> 1846506898 | E6: 2 | F6: =$E6*1000 -> 2000 | J6: =$E6*1000 -> 2000 | N6: =$E6*1000 -> 2000 | R6: =$E6*1000 -> 2000 | V6: =$E6*1000 -> 2000 | Z6: =$E6*1000 -> 2000 | AH6: =F6+G6+H6+J6+K6+L6+N6+O6+P6+R6+S6+T6+V6+W6+X6+Z6+AA6+AB6+AD6+AE6+AF6 -> 12000 | AI6: =I6+M6+Q6+U6+Y6+AC6+AG6 -> 0 | AK6: 0 | AL6: =IF(N(F6)>=$E6*1000,"",IF(AND($E6>0,AK6>=$E6*1000),"G",IF(F$2<=TODAY(),"R",""))) | AM6: =AK6-IF(AL6="G",$E6*1000,0)+N(G6) -> 0 | AN6: =IF(N(J6)>=$E6*1000,"",IF(AND($E6>0,AM6>=$E6*1000),"G",IF(J$2<=TODAY(),"R",""))) | AO6: =AM6-IF(AN6="G",$E6*1000,0)+N(K6) -> 0 | AP6: =IF(N(N6)>=$E6*1000,"",IF(AND($E6>0,AO6>=$E6*1000),"G",IF(N$2<=TODAY(),"R",""))) | AQ6: =AO6-IF(AP6="G",$E6*1000,0)+N(O6) -> 0 | AR6: =IF(N(R6)>=$E6*1000,"",IF(AND($E6>0,AQ6>=$E6*1000),"G",IF(R$2<=TODAY(),"R",""))) | AS6: =AQ6-IF(AR6="G",$E6*1000,0)+N(S6) -> 0 | AT6: =IF(N(V6)>=$E6*1000,"",IF(AND($E6>0,AS6>=$E6*1000),"G",IF(V$2<=TODAY(),"R",""))) | AU6: =AS6-IF(AT6="G",$E6*1000,0)+N(W6) -> 0 | AV6: =IF(N(Z6)>=$E6*1000,"",IF(AND($E6>0,AU6>=$E6*1000),"G",IF(Z$2<=TODAY(),"R",""))) | AW6: =AU6-IF(AV6="G",$E6*1000,0)+N(AA6) -> 0 | AX6: =IF(N(AD6)>=$E6*1000,"",IF(AND($E6>0,AW6>=$E6*1000),"G",IF(AD$2<=TODAY(),"R",""))) -> R | AY6: =AW6-IF(AX6="G",$E6*1000,0)+N(AE6) -> 0
B7: =ROW()-3 -> 4 | C7: Amanat Khan | D7: ='Member Wise Deposit Summary'!D7 -> 966551311461 | E7: 5 | F7: =$E7*1000 -> 5000 | J7: =$E7*1000 -> 5000 | N7: =$E7*1000 -> 5000 | R7: =$E7*1000 -> 5000 | V7: =$E7*1000 -> 5000 | Z7: =$E7*1000 -> 5000 | AD7: =$E7*1000 -> 5000 | AH7: =F7+G7+H7+J7+K7+L7+N7+O7+P7+R7+S7+T7+V7+W7+X7+Z7+AA7+AB7+AD7+AE7+AF7 -> 35000 | AI7: =I7+M7+Q7+U7+Y7+AC7+AG7 -> 0 | AK7: 0 | AL7: =IF(N(F7)>=$E7*1000,"",IF(AND($E7>0,AK7>=$E7*1000),"G",IF(F$2<=TODAY(),"R",""))) | AM7: =AK7-IF(AL7="G",$E7*1000,0)+N(G7) -> 0 | AN7: =IF(N(J7)>=$E7*1000,"",IF(AND($E7>0,AM7>=$E7*1000),"G",IF(J$2<=TODAY(),"R",""))) | AO7: =AM7-IF(AN7="G",$E7*1000,0)+N(K7) -> 0 | AP7: =IF(N(N7)>=$E7*1000,"",IF(AND($E7>0,AO7>=$E7*1000),"G",IF(N$2<=TODAY(),"R",""))) | AQ7: =AO7-IF(AP7="G",$E7*1000,0)+N(O7) -> 0 | AR7: =IF(N(R7)>=$E7*1000,"",IF(AND($E7>0,AQ7>=$E7*1000),"G",IF(R$2<=TODAY(),"R",""))) | AS7: =AQ7-IF(AR7="G",$E7*1000,0)+N(S7) -> 0 | AT7: =IF(N(V7)>=$E7*1000,"",IF(AND($E7>0,AS7>=$E7*1000),"G",IF(V$2<=TODAY(),"R",""))) | AU7: =AS7-IF(AT7="G",$E7*1000,0)+N(W7) -> 0 | AV7: =IF(N(Z7)>=$E7*1000,"",IF(AND($E7>0,AU7>=$E7*1000),"G",IF(Z$2<=TODAY(),"R",""))) | AW7: =AU7-IF(AV7="G",$E7*1000,0)+N(AA7) -> 0 | AX7: =IF(N(AD7)>=$E7*1000,"",IF(AND($E7>0,AW7>=$E7*1000),"G",IF(AD$2<=TODAY(),"R",""))) | AY7: =AW7-IF(AX7="G",$E7*1000,0)+N(AE7) -> 0
B8: =ROW()-3 -> 5 | C8: Nurunnabi Hosen Tanzid | D8: ='Member Wise Deposit Summary'!D8 -> 1838848678 | E8: 2 | F8: =$E8*1000 -> 2000 | J8: =$E8*1000 -> 2000 | N8: =$E8*1000 -> 2000 | R8: =$E8*1000 -> 2000 | V8: =$E8*1000 -> 2000 | Z8: =$E8*1000 -> 2000 | AD8: =$E8*1000 -> 2000 | AH8: =F8+G8+H8+J8+K8+L8+N8+O8+P8+R8+S8+T8+V8+W8+X8+Z8+AA8+AB8+AD8+AE8+AF8 -> 14000 | AI8: =I8+M8+Q8+U8+Y8+AC8+AG8 -> 0 | AK8: 0 | AL8: =IF(N(F8)>=$E8*1000,"",IF(AND($E8>0,AK8>=$E8*1000),"G",IF(F$2<=TODAY(),"R",""))) | AM8: =AK8-IF(AL8="G",$E8*1000,0)+N(G8) -> 0 | AN8: =IF(N(J8)>=$E8*1000,"",IF(AND($E8>0,AM8>=$E8*1000),"G",IF(J$2<=TODAY(),"R",""))) | AO8: =AM8-IF(AN8="G",$E8*1000,0)+N(K8) -> 0 | AP8: =IF(N(N8)>=$E8*1000,"",IF(AND($E8>0,AO8>=$E8*1000),"G",IF(N$2<=TODAY(),"R",""))) | AQ8: =AO8-IF(AP8="G",$E8*1000,0)+N(O8) -> 0 | AR8: =IF(N(R8)>=$E8*1000,"",IF(AND($E8>0,AQ8>=$E8*1000),"G",IF(R$2<=TODAY(),"R",""))) | AS8: =AQ8-IF(AR8="G",$E8*1000,0)+N(S8) -> 0 | AT8: =IF(N(V8)>=$E8*1000,"",IF(AND($E8>0,AS8>=$E8*1000),"G",IF(V$2<=TODAY(),"R",""))) | AU8: =AS8-IF(AT8="G",$E8*1000,0)+N(W8) -> 0 | AV8: =IF(N(Z8)>=$E8*1000,"",IF(AND($E8>0,AU8>=$E8*1000),"G",IF(Z$2<=TODAY(),"R",""))) | AW8: =AU8-IF(AV8="G",$E8*1000,0)+N(AA8) -> 0 | AX8: =IF(N(AD8)>=$E8*1000,"",IF(AND($E8>0,AW8>=$E8*1000),"G",IF(AD$2<=TODAY(),"R",""))) | AY8: =AW8-IF(AX8="G",$E8*1000,0)+N(AE8) -> 0
B9: =ROW()-3 -> 6 | C9: Jashim Uddin | D9: ='Member Wise Deposit Summary'!D9 -> 966538760537 | E9: 2 | F9: =$E9*1000 -> 2000 | J9: =$E9*1000 -> 2000 | N9: =$E9*1000 -> 2000 | R9: =$E9*1000 -> 2000 | S9: 8000 | AH9: =F9+G9+H9+J9+K9+L9+N9+O9+P9+R9+S9+T9+V9+W9+X9+Z9+AA9+AB9+AD9+AE9+AF9 -> 16000 | AI9: =I9+M9+Q9+U9+Y9+AC9+AG9 -> 0 | AK9: 0 | AL9: =IF(N(F9)>=$E9*1000,"",IF(AND($E9>0,AK9>=$E9*1000),"G",IF(F$2<=TODAY(),"R",""))) | AM9: =AK9-IF(AL9="G",$E9*1000,0)+N(G9) -> 0 | AN9: =IF(N(J9)>=$E9*1000,"",IF(AND($E9>0,AM9>=$E9*1000),"G",IF(J$2<=TODAY(),"R",""))) | AO9: =AM9-IF(AN9="G",$E9*1000,0)+N(K9) -> 0 | AP9: =IF(N(N9)>=$E9*1000,"",IF(AND($E9>0,AO9>=$E9*1000),"G",IF(N$2<=TODAY(),"R",""))) | AQ9: =AO9-IF(AP9="G",$E9*1000,0)+N(O9) -> 0 | AR9: =IF(N(R9)>=$E9*1000,"",IF(AND($E9>0,AQ9>=$E9*1000),"G",IF(R$2<=TODAY(),"R",""))) | AS9: =AQ9-IF(AR9="G",$E9*1000,0)+N(S9) -> 8000 | AT9: =IF(N(V9)>=$E9*1000,"",IF(AND($E9>0,AS9>=$E9*1000),"G",IF(V$2<=TODAY(),"R",""))) -> G | AU9: =AS9-IF(AT9="G",$E9*1000,0)+N(W9) -> 6000 | AV9: =IF(N(Z9)>=$E9*1000,"",IF(AND($E9>0,AU9>=$E9*1000),"G",IF(Z$2<=TODAY(),"R",""))) -> G | AW9: =AU9-IF(AV9="G",$E9*1000,0)+N(AA9) -> 4000 | AX9: =IF(N(AD9)>=$E9*1000,"",IF(AND($E9>0,AW9>=$E9*1000),"G",IF(AD$2<=TODAY(),"R",""))) -> G | AY9: =AW9-IF(AX9="G",$E9*1000,0)+N(AE9) -> 2000
B10: =ROW()-3 -> 7 | C10: Shibu Sankar Karmaker | D10: ='Member Wise Deposit Summary'!D10 -> 1885946523 | E10: 2 | F10: =$E10*1000 -> 2000 | J10: =$E10*1000 -> 2000 | N10: =$E10*1000 -> 2000 | R10: =$E10*1000 -> 2000 | V10: =$E10*1000 -> 2000 | Z10: =$E10*1000 -> 2000 | AD10: =$E10*1000 -> 2000 | AH10: =F10+G10+H10+J10+K10+L10+N10+O10+P10+R10+S10+T10+V10+W10+X10+Z10+AA10+AB10+AD10+AE10+AF10 -> 14000 | AI10: =I10+M10+Q10+U10+Y10+AC10+AG10 -> 0 | AK10: 0 | AL10: =IF(N(F10)>=$E10*1000,"",IF(AND($E10>0,AK10>=$E10*1000),"G",IF(F$2<=TODAY(),"R",""))) | AM10: =AK10-IF(AL10="G",$E10*1000,0)+N(G10) -> 0 | AN10: =IF(N(J10)>=$E10*1000,"",IF(AND($E10>0,AM10>=$E10*1000),"G",IF(J$2<=TODAY(),"R",""))) | AO10: =AM10-IF(AN10="G",$E10*1000,0)+N(K10) -> 0 | AP10: =IF(N(N10)>=$E10*1000,"",IF(AND($E10>0,AO10>=$E10*1000),"G",IF(N$2<=TODAY(),"R",""))) | AQ10: =AO10-IF(AP10="G",$E10*1000,0)+N(O10) -> 0 | AR10: =IF(N(R10)>=$E10*1000,"",IF(AND($E10>0,AQ10>=$E10*1000),"G",IF(R$2<=TODAY(),"R",""))) | AS10: =AQ10-IF(AR10="G",$E10*1000,0)+N(S10) -> 0 | AT10: =IF(N(V10)>=$E10*1000,"",IF(AND($E10>0,AS10>=$E10*1000),"G",IF(V$2<=TODAY(),"R",""))) | AU10: =AS10-IF(AT10="G",$E10*1000,0)+N(W10) -> 0 | AV10: =IF(N(Z10)>=$E10*1000,"",IF(AND($E10>0,AU10>=$E10*1000),"G",IF(Z$2<=TODAY(),"R",""))) | AW10: =AU10-IF(AV10="G",$E10*1000,0)+N(AA10) -> 0 | AX10: =IF(N(AD10)>=$E10*1000,"",IF(AND($E10>0,AW10>=$E10*1000),"G",IF(AD$2<=TODAY(),"R",""))) | AY10: =AW10-IF(AX10="G",$E10*1000,0)+N(AE10) -> 0
B11: =ROW()-3 -> 8 | C11: Monsur | D11: ='Member Wise Deposit Summary'!D11 -> 1608632799 | E11: 2 | F11: =$E11*1000 -> 2000 | J11: =$E11*1000 -> 2000 | N11: =$E11*1000 -> 2000 | R11: =$E11*1000 -> 2000 | V11: =$E11*1000 -> 2000 | Z11: =$E11*1000 -> 2000 | AD11: =$E11*1000 -> 2000 | AH11: =F11+G11+H11+J11+K11+L11+N11+O11+P11+R11+S11+T11+V11+W11+X11+Z11+AA11+AB11+AD11+AE11+AF11 -> 14000 | AI11: =I11+M11+Q11+U11+Y11+AC11+AG11 -> 0 | AK11: 0 | AL11: =IF(N(F11)>=$E11*1000,"",IF(AND($E11>0,AK11>=$E11*1000),"G",IF(F$2<=TODAY(),"R",""))) | AM11: =AK11-IF(AL11="G",$E11*1000,0)+N(G11) -> 0 | AN11: =IF(N(J11)>=$E11*1000,"",IF(AND($E11>0,AM11>=$E11*1000),"G",IF(J$2<=TODAY(),"R",""))) | AO11: =AM11-IF(AN11="G",$E11*1000,0)+N(K11) -> 0 | AP11: =IF(N(N11)>=$E11*1000,"",IF(AND($E11>0,AO11>=$E11*1000),"G",IF(N$2<=TODAY(),"R",""))) | AQ11: =AO11-IF(AP11="G",$E11*1000,0)+N(O11) -> 0 | AR11: =IF(N(R11)>=$E11*1000,"",IF(AND($E11>0,AQ11>=$E11*1000),"G",IF(R$2<=TODAY(),"R",""))) | AS11: =AQ11-IF(AR11="G",$E11*1000,0)+N(S11) -> 0 | AT11: =IF(N(V11)>=$E11*1000,"",IF(AND($E11>0,AS11>=$E11*1000),"G",IF(V$2<=TODAY(),"R",""))) | AU11: =AS11-IF(AT11="G",$E11*1000,0)+N(W11) -> 0 | AV11: =IF(N(Z11)>=$E11*1000,"",IF(AND($E11>0,AU11>=$E11*1000),"G",IF(Z$2<=TODAY(),"R",""))) | AW11: =AU11-IF(AV11="G",$E11*1000,0)+N(AA11) -> 0 | AX11: =IF(N(AD11)>=$E11*1000,"",IF(AND($E11>0,AW11>=$E11*1000),"G",IF(AD$2<=TODAY(),"R",""))) | AY11: =AW11-IF(AX11="G",$E11*1000,0)+N(AE11) -> 0
B12: =ROW()-3 -> 9 | C12: Monjur Alam | D12: ='Member Wise Deposit Summary'!D12 -> 1811938007 | E12: 2 | F12: =$E12*1000 -> 2000 | J12: =$E12*1000 -> 2000 | N12: =$E12*1000 -> 2000 | R12: =$E12*1000 -> 2000 | V12: =$E12*1000 -> 2000 | Z12: =$E12*1000 -> 2000 | AD12: =$E12*1000 -> 2000 | AH12: =F12+G12+H12+J12+K12+L12+N12+O12+P12+R12+S12+T12+V12+W12+X12+Z12+AA12+AB12+AD12+AE12+AF12 -> 14000 | AI12: =I12+M12+Q12+U12+Y12+AC12+AG12 -> 0 | AK12: 0 | AL12: =IF(N(F12)>=$E12*1000,"",IF(AND($E12>0,AK12>=$E12*1000),"G",IF(F$2<=TODAY(),"R",""))) | AM12: =AK12-IF(AL12="G",$E12*1000,0)+N(G12) -> 0 | AN12: =IF(N(J12)>=$E12*1000,"",IF(AND($E12>0,AM12>=$E12*1000),"G",IF(J$2<=TODAY(),"R",""))) | AO12: =AM12-IF(AN12="G",$E12*1000,0)+N(K12) -> 0 | AP12: =IF(N(N12)>=$E12*1000,"",IF(AND($E12>0,AO12>=$E12*1000),"G",IF(N$2<=TODAY(),"R",""))) | AQ12: =AO12-IF(AP12="G",$E12*1000,0)+N(O12) -> 0 | AR12: =IF(N(R12)>=$E12*1000,"",IF(AND($E12>0,AQ12>=$E12*1000),"G",IF(R$2<=TODAY(),"R",""))) | AS12: =AQ12-IF(AR12="G",$E12*1000,0)+N(S12) -> 0 | AT12: =IF(N(V12)>=$E12*1000,"",IF(AND($E12>0,AS12>=$E12*1000),"G",IF(V$2<=TODAY(),"R",""))) | AU12: =AS12-IF(AT12="G",$E12*1000,0)+N(W12) -> 0 | AV12: =IF(N(Z12)>=$E12*1000,"",IF(AND($E12>0,AU12>=$E12*1000),"G",IF(Z$2<=TODAY(),"R",""))) | AW12: =AU12-IF(AV12="G",$E12*1000,0)+N(AA12) -> 0 | AX12: =IF(N(AD12)>=$E12*1000,"",IF(AND($E12>0,AW12>=$E12*1000),"G",IF(AD$2<=TODAY(),"R",""))) | AY12: =AW12-IF(AX12="G",$E12*1000,0)+N(AE12) -> 0
B13: =ROW()-3 -> 10 | C13: Rupal Kanti Karmaker | D13: ='Member Wise Deposit Summary'!D13 -> 1812934934 | E13: 1 | F13: =$E13*1000 -> 1000 | J13: =$E13*1000 -> 1000 | N13: =$E13*1000 -> 1000 | R13: =$E13*1000 -> 1000 | V13: =$E13*1000 -> 1000 | Z13: =$E13*1000 -> 1000 | AD13: =$E13*1000 -> 1000 | AH13: =F13+G13+H13+J13+K13+L13+N13+O13+P13+R13+S13+T13+V13+W13+X13+Z13+AA13+AB13+AD13+AE13+AF13 -> 7000 | AI13: =I13+M13+Q13+U13+Y13+AC13+AG13 -> 0 | AK13: 0 | AL13: =IF(N(F13)>=$E13*1000,"",IF(AND($E13>0,AK13>=$E13*1000),"G",IF(F$2<=TODAY(),"R",""))) | AM13: =AK13-IF(AL13="G",$E13*1000,0)+N(G13) -> 0 | AN13: =IF(N(J13)>=$E13*1000,"",IF(AND($E13>0,AM13>=$E13*1000),"G",IF(J$2<=TODAY(),"R",""))) | AO13: =AM13-IF(AN13="G",$E13*1000,0)+N(K13) -> 0 | AP13: =IF(N(N13)>=$E13*1000,"",IF(AND($E13>0,AO13>=$E13*1000),"G",IF(N$2<=TODAY(),"R",""))) | AQ13: =AO13-IF(AP13="G",$E13*1000,0)+N(O13) -> 0 | AR13: =IF(N(R13)>=$E13*1000,"",IF(AND($E13>0,AQ13>=$E13*1000),"G",IF(R$2<=TODAY(),"R",""))) | AS13: =AQ13-IF(AR13="G",$E13*1000,0)+N(S13) -> 0 | AT13: =IF(N(V13)>=$E13*1000,"",IF(AND($E13>0,AS13>=$E13*1000),"G",IF(V$2<=TODAY(),"R",""))) | AU13: =AS13-IF(AT13="G",$E13*1000,0)+N(W13) -> 0 | AV13: =IF(N(Z13)>=$E13*1000,"",IF(AND($E13>0,AU13>=$E13*1000),"G",IF(Z$2<=TODAY(),"R",""))) | AW13: =AU13-IF(AV13="G",$E13*1000,0)+N(AA13) -> 0 | AX13: =IF(N(AD13)>=$E13*1000,"",IF(AND($E13>0,AW13>=$E13*1000),"G",IF(AD$2<=TODAY(),"R",""))) | AY13: =AW13-IF(AX13="G",$E13*1000,0)+N(AE13) -> 0
